<?xml version="1.0" ?>
<sdf version="1.8">
    <model name='movus'>
      <link name='chassis'>
        <pose>0 -0 0 0 -0 3.14</pose>
        <inertial>
          <mass>1.14395</mass>
          <inertia>
            <ixx>0.126164</ixx>
            <ixy>0</ixy>
            <ixz>0</ixz>
            <iyy>0.416519</iyy>
            <iyz>0</iyz>
            <izz>0.481014</izz>
          </inertia>
        </inertial>
        <visual name='visual_chassis'>
          <geometry>
            <box>
              <size>2.01142 1 0.568726</size>
            </box>
          </geometry>
          <material>
            <ambient>0.5 0.5 1.0 1</ambient>
            <diffuse>0.5 0.5 1.0 1</diffuse>
            <specular>0.0 0.0 1.0 1</specular>
          </material>
        </visual>
        <collision name='collision_chassis'>
          <geometry>
            <box>
              <size>2.01142 1 0.568726</size>
            </box>
          </geometry>
        </collision>
      </link>

      <link name='left_wheel'>
        <pose>0.554283 0.625029 -0.025 -1.5707 0 0</pose>
        <inertial>
          <mass>2</mass>
          <inertia>
            <ixx>0.145833</ixx>
            <ixy>0</ixy>
            <ixz>0</ixz>
            <iyy>0.145833</iyy>
            <iyz>0</iyz>
            <izz>0.125</izz>
          </inertia>
        </inertial>
        <visual name='visual_left_wheel'>
          <geometry>
            <sphere>
              <radius>0.3</radius>
            </sphere>
          </geometry>
          <material>
            <ambient>0.2 0.2 0.2 1</ambient>
            <diffuse>0.2 0.2 0.2 1</diffuse>
            <specular>0.2 0.2 0.2 1</specular>
          </material>
        </visual>
        <collision name='collision_left_wheel'>
          <geometry>
            <sphere>
              <radius>0.3</radius>
            </sphere>
          </geometry>
        </collision>
      </link>

      <link name='right_wheel'>
        <pose>0.554282 -0.625029 -0.025 -1.5707 0 0</pose>
        <inertial>
          <mass>2</mass>
          <inertia>
            <ixx>0.145833</ixx>
            <ixy>0</ixy>
            <ixz>0</ixz>
            <iyy>0.145833</iyy>
            <iyz>0</iyz>
            <izz>0.125</izz>
          </inertia>
        </inertial>
        <visual name='visual_right_wheel'>
          <geometry>
            <sphere>
              <radius>0.3</radius>
            </sphere>
          </geometry>
          <material>
            <ambient>0.2 0.2 0.2 1</ambient>
            <diffuse>0.2 0.2 0.2 1</diffuse>
            <specular>0.2 0.2 0.2 1</specular>
          </material>
        </visual>
        <collision name='collision_right_wheel'>
          <geometry>
            <sphere>
              <radius>0.3</radius>
            </sphere>
          </geometry>
        </collision>
      </link>

      <link name='caster'>
        <pose>-0.957138 -0 -0.125 0 -0 0</pose>
        <inertial>
          <mass>1</mass>
          <inertia>
            <ixx>0.1</ixx>
            <ixy>0</ixy>
            <ixz>0</ixz>
            <iyy>0.1</iyy>
            <iyz>0</iyz>
            <izz>0.1</izz>
          </inertia>
        </inertial>
        <visual name='visual_caster'>
          <geometry>
            <sphere>
              <radius>0.2</radius>
            </sphere>
          </geometry>
          <material>
            <ambient>0.2 0.2 0.2 1</ambient>
            <diffuse>0.2 0.2 0.2 1</diffuse>
            <specular>0.2 0.2 0.2 1</specular>
          </material>
        </visual>
        <collision name='collision_caster'>
          <geometry>
            <sphere>
              <radius>0.2</radius>
            </sphere>
          </geometry>
        </collision>
      </link>

      <!-- camera_config -->
      <!-- Camera Link -->
      <link name="camera_link">
        <pose>0.5 0 0.7 0 0 0</pose>
        <sensor name="camera_sensor" type="camera">
          <pose>0 0 0 0 0 0</pose>
          <update_rate>30</update_rate>
          <camera>
            <horizontal_fov>1.22</horizontal_fov>
            <image>
              <width>640</width>
              <height>480</height>
              <format>R8G8B8</format>
            </image>
            <clip>
              <near>0.1</near>
              <far>50</far>
            </clip>
            <noise>
              <type>gaussian</type>
              <mean>0.0</mean>
              <stddev>0.01</stddev>
            </noise>
          </camera>
          <visualize>true</visualize>
          <topic>/camera/image</topic>
        </sensor>
      </link>

      <!-- Camera Joint -->
      <joint name="camera_joint" type="fixed">
        <parent>chassis</parent>
        <child>camera_link</child>
      </joint>

      <!-- camera_front_optical_frame -->

      <link name="camera_front_optical_frame">
        <pose relative_to="camera_front">0 0 0 -1.57 0 -1.57</pose>
        <sensor name="camera1" type="rgbd_camera">
          <camera>
            <horizontal_fov>1.047</horizontal_fov>
            <image>
              <width>320</width>
              <height>240</height>
            </image>
            <clip>
              <near>0.1</near>
              <far>100</far>
            </clip>
          </camera>
          <always_on>1</always_on>
          <update_rate>30</update_rate>
          <visualize>true</visualize>
          <!-- <topic>camera</topic> -->
        </sensor>
      </link>

      <joint name="camera_front_optical_joint" type="fixed">
        <child>camera_front_optical_frame</child>
        <parent>camera_front</parent>
      </joint>

      <!-- camera_front -->
      <link name="camera_front">
          <pose relative_to="chassis">0.6 0 -0.05 0 0 0</pose>
      </link>

      <joint name="camera_front_joint" type="fixed">
        <child>camera_front</child>
        <parent>chassis</parent>
      </joint>

      <!-- camera_depth_frame -->

      <link name="camera_depth_frame">
        <pose relative_to="camera_front">0 0 0 0 0 0</pose>
        <sensor name="camera_with_intrinsics_tag" type="depth">
          <pose>0 0 0 0 0 0</pose>
          <update_rate>6</update_rate>
          <always_on>1</always_on>
          <camera>
            <horizontal_fov>1.22</horizontal_fov>
            <image>
              <width>640</width>
              <height>480</height>
              <!-- <format>R_FLOAT32</format> -->
              <format>R8G8B8</format>
            </image>
            <clip>
              <near>0.1</near>
              <far>3</far>
            </clip>
            <lens>
              <intrinsics>
                <fx>421.61578369140625</fx>
                <fy>421.61578369140625</fy>
                <cx>422.2854309082031</cx>
                <cy>236.57237243652344</cy>
                <s>0</s>
              </intrinsics>
            </lens>
          </camera>
        </sensor>
      </link>

      <joint name="camera_depth_joint" type="fixed">
        <child>camera_depth_frame</child>
        <parent>chassis</parent>
      </joint>


      <!-- camera config end -->

      <joint name='left_wheel_joint' type='revolute'>
        <parent>chassis</parent>
        <child>left_wheel</child>
        <axis>
          <xyz>0 0 1</xyz>
          <limit>
            <lower>-1.79769e+308</lower>
            <upper>1.79769e+308</upper>
          </limit>
        </axis>
      </joint>

      <joint name='right_wheel_joint' type='revolute'>
        <parent>chassis</parent>
        <child>right_wheel</child>
        <axis>
          <xyz>0 0 1</xyz>
          <limit>
            <lower>-1.79769e+308</lower>
            <upper>1.79769e+308</upper>
          </limit>
        </axis>
      </joint>

      <joint name='caster_wheel' type='ball'>
        <parent>chassis</parent>
        <child>caster</child>
      </joint>

      <plugin
        filename="gz-sim-odometry-publisher-system"
        name="gz::sim::systems::OdometryPublisher">
        <odom_frame>map</odom_frame>
        <robot_base_frame>chassis</robot_base_frame>
        <dimensions>3</dimensions>
        <odom_publish_frequency>10</odom_publish_frequency>
      </plugin>

      <plugin
        filename="gz-sim-diff-drive-system"
        name="gz::sim::systems::DiffDrive">
        <left_joint>left_wheel_joint</left_joint>
        <right_joint>right_wheel_joint</right_joint>
        <wheel_separation>1.25</wheel_separation>
        <wheel_radius>0.3</wheel_radius>
        <!-- <odom_publish_frequency>5</odom_publish_frequency> -->
        <!-- <frame_id>map</frame_id> -->
        <!-- <child_frame_id>base_link</child_frame_id> --> 
        <max_linear_acceleration>1</max_linear_acceleration>
        <min_linear_acceleration>-1</min_linear_acceleration>
        <max_angular_acceleration>2</max_angular_acceleration>
        <min_angular_acceleration>-2</min_angular_acceleration>
        <max_linear_velocity>0.5</max_linear_velocity>
        <min_linear_velocity>-0.5</min_linear_velocity>
        <max_angular_velocity>1</max_angular_velocity>
        <min_angular_velocity>-1</min_angular_velocity>
      </plugin>

      <!-- <plugin
      filename="gz-sim-components"
      name="gz::sim::Componenets">
      </plugin> -->
    
      
      <plugin
        filename="gz-sim-sensors-system"
        name="gz::sim::systems::Sensors">
        <!-- <render_engine>ogre2</render_engine> -->
      </plugin>

      <plugin
        filename="gz-sim-user-commands-system"
        name="gz::sim::systems::UserCommands">
      </plugin>
      
      <plugin
        filename="gz-sim-scene-broadcaster-system"
        name="gz::sim::systems::SceneBroadcaster">
      </plugin>

      
    </model>
</sdf>
